<?xml version="1.0" encoding="UTF-8"?>
<testng-results skipped="0" failed="1" ignored="0" total="1" passed="0">
  <reporter-output>
  </reporter-output>
  <suite name="Default suite" duration-ms="53531" started-at="2022-05-07T19:22:59Z" finished-at="2022-05-07T19:23:53Z">
    <groups>
    </groups>
    <test name="Default test" duration-ms="53531" started-at="2022-05-07T19:22:59Z" finished-at="2022-05-07T19:23:53Z">
      <class name="TestScripts.Test_Script">
        <test-method status="PASS" signature="openapp()[pri:0, instance:TestScripts.Test_Script@66a3ffec]" name="openapp" is-config="true" duration-ms="19064" started-at="2022-05-07T19:22:59Z" finished-at="2022-05-07T19:23:18Z">
          <reporter-output>
          </reporter-output>
        </test-method> <!-- openapp -->
        <test-method status="FAIL" signature="test()[pri:0, instance:TestScripts.Test_Script@66a3ffec]" name="test" duration-ms="34129" started-at="2022-05-07T19:23:18Z" finished-at="2022-05-07T19:23:52Z">
          <exception class="java.lang.AssertionError">
            <message>
              <![CDATA[expected [Thanks for submitting] but found []]]>
            </message>
            <full-stacktrace>
              <![CDATA[java.lang.AssertionError: expected [Thanks for submitting] but found []
at org.testng.Assert.fail(Assert.java:96)
at org.testng.Assert.failNotEquals(Assert.java:776)
at org.testng.Assert.assertEqualsImpl(Assert.java:137)
at org.testng.Assert.assertEquals(Assert.java:118)
at org.testng.Assert.assertEquals(Assert.java:453)
at org.testng.Assert.assertEquals(Assert.java:463)
at TestScripts.Test_Script.test(Test_Script.java:101)
at sun.reflect.NativeMethodAccessorImpl.invoke0(Native Method)
at sun.reflect.NativeMethodAccessorImpl.invoke(NativeMethodAccessorImpl.java:62)
at sun.reflect.DelegatingMethodAccessorImpl.invoke(DelegatingMethodAccessorImpl.java:43)
at java.lang.reflect.Method.invoke(Method.java:498)
at org.testng.internal.MethodInvocationHelper.invokeMethod(MethodInvocationHelper.java:124)
at org.testng.internal.Invoker.invokeMethod(Invoker.java:583)
at org.testng.internal.Invoker.invokeTestMethod(Invoker.java:719)
at org.testng.internal.Invoker.invokeTestMethods(Invoker.java:989)
at org.testng.internal.TestMethodWorker.invokeTestMethods(TestMethodWorker.java:125)
at org.testng.internal.TestMethodWorker.run(TestMethodWorker.java:109)
at org.testng.TestRunner.privateRun(TestRunner.java:648)
at org.testng.TestRunner.run(TestRunner.java:505)
at org.testng.SuiteRunner.runTest(SuiteRunner.java:455)
at org.testng.SuiteRunner.runSequentially(SuiteRunner.java:450)
at org.testng.SuiteRunner.privateRun(SuiteRunner.java:415)
at org.testng.SuiteRunner.run(SuiteRunner.java:364)
at org.testng.SuiteRunnerWorker.runSuite(SuiteRunnerWorker.java:52)
at org.testng.SuiteRunnerWorker.run(SuiteRunnerWorker.java:84)
at org.testng.TestNG.runSuitesSequentially(TestNG.java:1208)
at org.testng.TestNG.runSuitesLocally(TestNG.java:1137)
at org.testng.TestNG.runSuites(TestNG.java:1049)
at org.testng.TestNG.run(TestNG.java:1017)
at org.testng.remote.AbstractRemoteTestNG.run(AbstractRemoteTestNG.java:114)
at org.testng.remote.RemoteTestNG.initAndRun(RemoteTestNG.java:251)
at org.testng.remote.RemoteTestNG.main(RemoteTestNG.java:77)
]]>
            </full-stacktrace>
          </exception> <!-- java.lang.AssertionError -->
          <reporter-output>
          </reporter-output>
        </test-method> <!-- test -->
        <test-method status="FAIL" signature="closeapp(org.testng.ITestResult)[pri:0, instance:TestScripts.Test_Script@66a3ffec]" name="closeapp" is-config="true" duration-ms="275" started-at="2022-05-07T19:23:52Z" finished-at="2022-05-07T19:23:53Z">
          <params>
            <param index="0">
              <value>
                <![CDATA[[TestResult name=test status=FAILURE method=Test_Script.test()[pri:0, instance:TestScripts.Test_Script@66a3ffec] output={null}]]]>
              </value>
            </param>
          </params>
          <exception class="java.io.FileNotFoundException">
            <message>
              <![CDATA[.\photos\Sun May 08 00:53:52 IST 2022.jpeg (The filename, directory name, or volume label syntax is incorrect)]]>
            </message>
            <full-stacktrace>
              <![CDATA[java.io.FileNotFoundException: .\photos\Sun May 08 00:53:52 IST 2022.jpeg (The filename, directory name, or volume label syntax is incorrect)
at java.io.FileOutputStream.open0(Native Method)
at java.io.FileOutputStream.open(FileOutputStream.java:270)
at java.io.FileOutputStream.<init>(FileOutputStream.java:213)
at java.io.FileOutputStream.<init>(FileOutputStream.java:162)
at org.openqa.selenium.io.FileHandler.copyFile(FileHandler.java:138)
at org.openqa.selenium.io.FileHandler.copy(FileHandler.java:117)
at Generic.Genric_Screenshot.getPhoto(Genric_Screenshot.java:21)
at Generic.BaseClass.closeapp(BaseClass.java:32)
at sun.reflect.NativeMethodAccessorImpl.invoke0(Native Method)
at sun.reflect.NativeMethodAccessorImpl.invoke(NativeMethodAccessorImpl.java:62)
at sun.reflect.DelegatingMethodAccessorImpl.invoke(DelegatingMethodAccessorImpl.java:43)
at java.lang.reflect.Method.invoke(Method.java:498)
at org.testng.internal.MethodInvocationHelper.invokeMethod(MethodInvocationHelper.java:124)
at org.testng.internal.MethodInvocationHelper.invokeMethodConsideringTimeout(MethodInvocationHelper.java:59)
at org.testng.internal.Invoker.invokeConfigurationMethod(Invoker.java:458)
at org.testng.internal.Invoker.invokeConfigurations(Invoker.java:222)
at org.testng.internal.Invoker.invokeMethod(Invoker.java:646)
at org.testng.internal.Invoker.invokeTestMethod(Invoker.java:719)
at org.testng.internal.Invoker.invokeTestMethods(Invoker.java:989)
at org.testng.internal.TestMethodWorker.invokeTestMethods(TestMethodWorker.java:125)
at org.testng.internal.TestMethodWorker.run(TestMethodWorker.java:109)
at org.testng.TestRunner.privateRun(TestRunner.java:648)
at org.testng.TestRunner.run(TestRunner.java:505)
at org.testng.SuiteRunner.runTest(SuiteRunner.java:455)
at org.testng.SuiteRunner.runSequentially(SuiteRunner.java:450)
at org.testng.SuiteRunner.privateRun(SuiteRunner.java:415)
at org.testng.SuiteRunner.run(SuiteRunner.java:364)
at org.testng.SuiteRunnerWorker.runSuite(SuiteRunnerWorker.java:52)
at org.testng.SuiteRunnerWorker.run(SuiteRunnerWorker.java:84)
at org.testng.TestNG.runSuitesSequentially(TestNG.java:1208)
at org.testng.TestNG.runSuitesLocally(TestNG.java:1137)
at org.testng.TestNG.runSuites(TestNG.java:1049)
at org.testng.TestNG.run(TestNG.java:1017)
at org.testng.remote.AbstractRemoteTestNG.run(AbstractRemoteTestNG.java:114)
at org.testng.remote.RemoteTestNG.initAndRun(RemoteTestNG.java:251)
at org.testng.remote.RemoteTestNG.main(RemoteTestNG.java:77)
]]>
            </full-stacktrace>
          </exception> <!-- java.io.FileNotFoundException -->
          <reporter-output>
          </reporter-output>
        </test-method> <!-- closeapp -->
      </class> <!-- TestScripts.Test_Script -->
    </test> <!-- Default test -->
  </suite> <!-- Default suite -->
</testng-results>
